Workbook

Sheet Catálogo
A1: Incluir | B1: Nombre | C1: Marca | D1: Categoría | E1: Precio referencia | F1: Oferta referencia | G1: Precio NAC | H1: Oferta NAC | I1: Precio manual | J1: Sabores / tamaños | K1: Stock | L1: Más vendido | M1: Nuevo | N1: Archivo de foto | O1: Notas
A2: Sí | B2: Creatina Platinum MuscleTech | C2: MuscleTech | D2: Creatinas | E2: 139000 | G2: =IF(I2<>"",I2,ROUND(E2*(1-Ajustes!$B$3),-3)) -> 118000 | H2: =IF(F2="","",ROUND(F2*(1-Ajustes!$B$3),-3)) | J2: Ej: Chocolate, Vainilla | K2: 10 | L2: Sí | M2: No | N2: products/creatina-platinum-muscletech.jpg | O2: Tenía rango hasta $147.000: agrega tamaños en Sabores/tamaños
A3: Sí | B3: Iso 100 5LB | C3: Dymatize | D3: Proteínas limpias | E3: 620000 | F3: 591000 | G3: =IF(I3<>"",I3,ROUND(E3*(1-Ajustes!$B$3),-3)) -> 527000 | H3: =IF(F3="","",ROUND(F3*(1-Ajustes!$B$3),-3)) -> 502000 | K3: 10 | L3: Sí | M3: No | N3: products/iso-100-5lb.jpg
A4: Sí | B4: TNT Mega Mass Gainer 10LB | C4: TNT | D4: Hipercalóricos | E4: 245000 | F4: 237000 | G4: =IF(I4<>"",I4,ROUND(E4*(1-Ajustes!$B$3),-3)) -> 208000 | H4: =IF(F4="","",ROUND(F4*(1-Ajustes!$B$3),-3)) -> 201000 | K4: 10 | L4: Sí | M4: No | N4: products/tnt-mega-mass-gainer-10lb.jpg
A5: Sí | B5: Nitro Tech Whey Gold 5LB | C5: MuscleTech | D5: Proteínas limpias | E5: 420000 | F5: 393000 | G5: =IF(I5<>"",I5,ROUND(E5*(1-Ajustes!$B$3),-3)) -> 357000 | H5: =IF(F5="","",ROUND(F5*(1-Ajustes!$B$3),-3)) -> 334000 | K5: 10 | L5: Sí | M5: No | N5: products/nitro-tech-whey-gold-5lb.jpg
A6: Sí | B6: 100% Whey Gold Standard 5LB | C6: Optimum Nutrition | D6: Proteínas limpias | E6: 500000 | F6: 465000 | G6: =IF(I6<>"",I6,ROUND(E6*(1-Ajustes!$B$3),-3)) -> 425000 | H6: =IF(F6="","",ROUND(F6*(1-Ajustes!$B$3),-3)) -> 395000 | K6: 10 | L6: Sí | M6: No | N6: products/100-whey-gold-standard-5lb.jpg
A7: Sí | B7: CR7INE Dynamic 450G | C7: Otras marcas (verificar) | D7: Creatinas | E7: 96000 | F7: 69000 | G7: =IF(I7<>"",I7,ROUND(E7*(1-Ajustes!$B$3),-3)) -> 82000 | H7: =IF(F7="","",ROUND(F7*(1-Ajustes!$B$3),-3)) -> 59000 | K7: 10 | L7: Sí | M7: No | N7: products/cr7ine-dynamic-450g.jpg | O7: Verificar marca
A8: Sí | B8: Bipro Classic 3LB | C8: Nutramerican | D8: Proteínas limpias | E8: 290000 | F8: 264000 | G8: =IF(I8<>"",I8,ROUND(E8*(1-Ajustes!$B$3),-3)) -> 247000 | H8: =IF(F8="","",ROUND(F8*(1-Ajustes!$B$3),-3)) -> 224000 | K8: 10 | L8: Sí | M8: No | N8: products/bipro-classic-3lb.jpg
A9: Sí | B9: Nitro Tech 4LB | C9: MuscleTech | D9: Proteínas limpias | E9: 370000 | F9: 347000 | G9: =IF(I9<>"",I9,ROUND(E9*(1-Ajustes!$B$3),-3)) -> 315000 | H9: =IF(F9="","",ROUND(F9*(1-Ajustes!$B$3),-3)) -> 295000 | K9: 10 | L9: Sí | M9: No | N9: products/nitro-tech-4lb.jpg
A10: Sí | B10: Whey Pure 5LB | C10: Nutramerican | D10: Proteínas limpias | E10: 311000 | G10: =IF(I10<>"",I10,ROUND(E10*(1-Ajustes!$B$3),-3)) -> 264000 | H10: =IF(F10="","",ROUND(F10*(1-Ajustes!$B$3),-3)) | K10: 10 | L10: Sí | M10: No | N10: products/whey-pure-5lb.jpg
A11: Sí | B11: 100% Whey Gold Standard 2LB | C11: Optimum Nutrition | D11: Proteínas limpias | E11: 280000 | F11: 256000 | G11: =IF(I11<>"",I11,ROUND(E11*(1-Ajustes!$B$3),-3)) -> 238000 | H11: =IF(F11="","",ROUND(F11*(1-Ajustes!$B$3),-3)) -> 218000 | K11: 10 | L11: Sí | M11: No | N11: products/100-whey-gold-standard-2lb.jpg
A12: Sí | B12: Bipro Classic 2LB | C12: Nutramerican | D12: Proteínas limpias | E12: 210000 | G12: =IF(I12<>"",I12,ROUND(E12*(1-Ajustes!$B$3),-3)) -> 179000 | H12: =IF(F12="","",ROUND(F12*(1-Ajustes!$B$3),-3)) | K12: 10 | L12: Sí | M12: No | N12: products/bipro-classic-2lb.jpg
A13: Sí | B13: Smart Gainer 3LB | C13: Nutramerican | D13: Hipercalóricos | E13: 120000 | F13: 101000 | G13: =IF(I13<>"",I13,ROUND(E13*(1-Ajustes!$B$3),-3)) -> 102000 | H13: =IF(F13="","",ROUND(F13*(1-Ajustes!$B$3),-3)) -> 86000 | K13: 10 | L13: Sí | M13: No | N13: products/smart-gainer-3lb.jpg
A14: Sí | B14: Carnivor 0 4LB | C14: MuscleMeds | D14: Proteínas limpias | E14: 314000 | F14: 287000 | G14: =IF(I14<>"",I14,ROUND(E14*(1-Ajustes!$B$3),-3)) -> 267000 | H14: =IF(F14="","",ROUND(F14*(1-Ajustes!$B$3),-3)) -> 244000 | K14: 10 | L14: Sí | M14: No | N14: products/carnivor-0-4lb.jpg
A15: Sí | B15: Crea Stack 60 Servicios | C15: Otras marcas (verificar) | D15: Creatinas | E15: 140000 | G15: =IF(I15<>"",I15,ROUND(E15*(1-Ajustes!$B$3),-3)) -> 119000 | H15: =IF(F15="","",ROUND(F15*(1-Ajustes!$B$3),-3)) | K15: 10 | L15: Sí | M15: No | N15: products/crea-stack-60-servicios.jpg | O15: Verificar marca
A16: Sí | B16: Platinum Multivitaminico 90 Tabletas | C16: MuscleTech | D16: Multivitamínicos | E16: 87000 | G16: =IF(I16<>"",I16,ROUND(E16*(1-Ajustes!$B$3),-3)) -> 74000 | H16: =IF(F16="","",ROUND(F16*(1-Ajustes!$B$3),-3)) | K16: 10 | L16: Sí | M16: No | N16: products/platinum-multivitaminico-90-tabletas.jpg
A17: Sí | B17: Atomic HCL 600G | C17: Otras marcas (verificar) | D17: Creatinas | E17: 108000 | F17: 86000 | G17: =IF(I17<>"",I17,ROUND(E17*(1-Ajustes!$B$3),-3)) -> 92000 | H17: =IF(F17="","",ROUND(F17*(1-Ajustes!$B$3),-3)) -> 73000 | K17: 10 | L17: Sí | M17: No | N17: products/atomic-hcl-600g.jpg | O17: Verificar marca
A18: Sí | B18: Legacy 50 Servicios | C18: Otras marcas (verificar) | D18: Creatinas | E18: 136000 | F18: 121000 | G18: =IF(I18<>"",I18,ROUND(E18*(1-Ajustes!$B$3),-3)) -> 116000 | H18: =IF(F18="","",ROUND(F18*(1-Ajustes!$B$3),-3)) -> 103000 | K18: 10 | L18: Sí | M18: No | N18: products/legacy-50-servicios.jpg | O18: Verificar marca
A19: Sí | B19: Creactor | C19: Otras marcas (verificar) | D19: Creatinas | E19: 160000 | F19: 137000 | G19: =IF(I19<>"",I19,ROUND(E19*(1-Ajustes!$B$3),-3)) -> 136000 | H19: =IF(F19="","",ROUND(F19*(1-Ajustes!$B$3),-3)) -> 116000 | K19: 10 | L19: Sí | M19: No | N19: products/creactor.jpg | O19: Verificar marca
A20: Sí | B20: Creatina Optimum Nutrition 600G | C20: Optimum Nutrition | D20: Creatinas | E20: 190000 | G20: =IF(I20<>"",I20,ROUND(E20*(1-Ajustes!$B$3),-3)) -> 162000 | H20: =IF(F20="","",ROUND(F20*(1-Ajustes!$B$3),-3)) | K20: 10 | L20: Sí | M20: No | N20: products/creatina-optimum-nutrition-600g.jpg
A21: Sí | B21: 100% Whey Gold Standard 10LB | C21: Optimum Nutrition | D21: Proteínas limpias | E21: 734000 | F21: 714000 | G21: =IF(I21<>"",I21,ROUND(E21*(1-Ajustes!$B$3),-3)) -> 624000 | H21: =IF(F21="","",ROUND(F21*(1-Ajustes!$B$3),-3)) -> 607000 | K21: 10 | L21: No | M21: No | N21: products/100-whey-gold-standard-10lb.jpg
A22: Sí | B22: Iso 100 3LB | C22: Dymatize | D22: Proteínas limpias | E22: 480000 | F22: 444000 | G22: =IF(I22<>"",I22,ROUND(E22*(1-Ajustes!$B$3),-3)) -> 408000 | H22: =IF(F22="","",ROUND(F22*(1-Ajustes!$B$3),-3)) -> 377000 | K22: 10 | L22: No | M22: No | N22: products/iso-100-3lb.jpg
A23: Sí | B23: Nitro Tech 2LB | C23: MuscleTech | D23: Proteínas limpias | E23: 250000 | F23: 233000 | G23: =IF(I23<>"",I23,ROUND(E23*(1-Ajustes!$B$3),-3)) -> 213000 | H23: =IF(F23="","",ROUND(F23*(1-Ajustes!$B$3),-3)) -> 198000 | K23: 10 | L23: No | M23: No | N23: products/nitro-tech-2lb.jpg
A24: Sí | B24: Nitro Tech 10LB | C24: MuscleTech | D24: Proteínas limpias | E24: 540000 | F24: 512000 | G24: =IF(I24<>"",I24,ROUND(E24*(1-Ajustes!$B$3),-3)) -> 459000 | H24: =IF(F24="","",ROUND(F24*(1-Ajustes!$B$3),-3)) -> 435000 | K24: 10 | L24: No | M24: No | N24: products/nitro-tech-10lb.jpg
A25: Sí | B25: Nitro Tech Ripped 4LB | C25: MuscleTech | D25: Proteínas limpias | E25: 342000 | F25: 317000 | G25: =IF(I25<>"",I25,ROUND(E25*(1-Ajustes!$B$3),-3)) -> 291000 | H25: =IF(F25="","",ROUND(F25*(1-Ajustes!$B$3),-3)) -> 269000 | K25: 10 | L25: No | M25: No | N25: products/nitro-tech-ripped-4lb.jpg
A26: Sí | B26: Syntha 6 5LB | C26: BSN | D26: Proteínas limpias | E26: 360000 | F26: 342000 | G26: =IF(I26<>"",I26,ROUND(E26*(1-Ajustes!$B$3),-3)) -> 306000 | H26: =IF(F26="","",ROUND(F26*(1-Ajustes!$B$3),-3)) -> 291000 | K26: 10 | L26: No | M26: No | N26: products/syntha-6-5lb.jpg
A27: Sí | B27: Serious Mass 6LB | C27: Optimum Nutrition | D27: Hipercalóricos | E27: 258000 | F27: 238000 | G27: =IF(I27<>"",I27,ROUND(E27*(1-Ajustes!$B$3),-3)) -> 219000 | H27: =IF(F27="","",ROUND(F27*(1-Ajustes!$B$3),-3)) -> 202000 | K27: 10 | L27: No | M27: No | N27: products/serious-mass-6lb.jpg
A28: Sí | B28: PASE Día de Muertos 2026 | C28: Otras marcas (verificar) | D28: Pre-entrenos | E28: 98000 | G28: =IF(I28<>"",I28,ROUND(E28*(1-Ajustes!$B$3),-3)) -> 83000 | H28: =IF(F28="","",ROUND(F28*(1-Ajustes!$B$3),-3)) | K28: 10 | L28: No | M28: Sí | N28: products/pase-dia-de-muertos-2026.jpg | O28: Verificar marca
A29: Sí | B29: Intenze Halloween 2026 | C29: Otras marcas (verificar) | D29: Pre-entrenos | E29: 155000 | F29: 130000 | G29: =IF(I29<>"",I29,ROUND(E29*(1-Ajustes!$B$3),-3)) -> 132000 | H29: =IF(F29="","",ROUND(F29*(1-Ajustes!$B$3),-3)) -> 111000 | K29: 10 | L29: No | M29: Sí | N29: products/intenze-halloween-2026.jpg | O29: Verificar marca
A30: Sí | B30: V-Gana PRO 1.5LB | C30: Otras marcas (verificar) | D30: Proteínas limpias | E30: 99000 | G30: =IF(I30<>"",I30,ROUND(E30*(1-Ajustes!$B$3),-3)) -> 84000 | H30: =IF(F30="","",ROUND(F30*(1-Ajustes!$B$3),-3)) | K30: 10 | L30: No | M30: Sí | N30: products/v-gana-pro-1-5lb.jpg | O30: Verificar marca
A31: Sí | B31: Creatina IMN 500G | C31: IMN | D31: Creatinas | E31: 118000 | G31: =IF(I31<>"",I31,ROUND(E31*(1-Ajustes!$B$3),-3)) -> 100000 | H31: =IF(F31="","",ROUND(F31*(1-Ajustes!$B$3),-3)) | K31: 10 | L31: No | M31: Sí | N31: products/creatina-imn-500g.jpg
A32: Sí | B32: Lata C4 Energy Original (12 Unidades) | C32: Cellucor | D32: Pre-entrenos | E32: 168000 | G32: =IF(I32<>"",I32,ROUND(E32*(1-Ajustes!$B$3),-3)) -> 143000 | H32: =IF(F32="","",ROUND(F32*(1-Ajustes!$B$3),-3)) | K32: 10 | L32: No | M32: Sí | N32: products/lata-c4-energy-original-12-unidades.jpg
A33: Sí | B33: C4 Original 60 Servicios | C33: Cellucor | D33: Pre-entrenos | E33: 160000 | G33: =IF(I33<>"",I33,ROUND(E33*(1-Ajustes!$B$3),-3)) -> 136000 | H33: =IF(F33="","",ROUND(F33*(1-Ajustes!$B$3),-3)) | K33: 10 | L33: No | M33: Sí | N33: products/c4-original-60-servicios.jpg
A34: Sí | B34: C4 Original 30 Servicios | C34: Cellucor | D34: Pre-entrenos | E34: 120000 | G34: =IF(I34<>"",I34,ROUND(E34*(1-Ajustes!$B$3),-3)) -> 102000 | H34: =IF(F34="","",ROUND(F34*(1-Ajustes!$B$3),-3)) | K34: 10 | L34: No | M34: Sí | N34: products/c4-original-30-servicios.jpg
A35: Sí | B35: Prime W Collagen Stack | C35: Otras marcas (verificar) | D35: Multivitamínicos | E35: 81000 | G35: =IF(I35<>"",I35,ROUND(E35*(1-Ajustes!$B$3),-3)) -> 69000 | H35: =IF(F35="","",ROUND(F35*(1-Ajustes!$B$3),-3)) | K35: 10 | L35: No | M35: Sí | N35: products/prime-w-collagen-stack.jpg | O35: Verificar marca
A36: Sí | B36: Creatina Forcehold Healthy Sports 120 Gomitas | C36: Healthy Sports | D36: Creatinas | E36: 92000 | G36: =IF(I36<>"",I36,ROUND(E36*(1-Ajustes!$B$3),-3)) -> 78000 | H36: =IF(F36="","",ROUND(F36*(1-Ajustes!$B$3),-3)) | K36: 10 | L36: No | M36: Sí | N36: products/creatina-forcehold-healthy-sports-120-gomitas.jpg
A37: Sí | B37: Crea Gold 600G Alpha Bull | C37: Alpha Bull | D37: Creatinas | E37: 112000 | G37: =IF(I37<>"",I37,ROUND(E37*(1-Ajustes!$B$3),-3)) -> 95000 | H37: =IF(F37="","",ROUND(F37*(1-Ajustes!$B$3),-3)) | K37: 10 | L37: No | M37: Sí | N37: products/crea-gold-600g-alpha-bull.jpg
A38: Sí | B38: Crea Gold 300G Alpha Bull | C38: Alpha Bull | D38: Creatinas | E38: 71000 | G38: =IF(I38<>"",I38,ROUND(E38*(1-Ajustes!$B$3),-3)) -> 60000 | H38: =IF(F38="","",ROUND(F38*(1-Ajustes!$B$3),-3)) | K38: 10 | L38: No | M38: Sí | N38: products/crea-gold-300g-alpha-bull.jpg
A39: Sí | B39: Crea Gold 150G Alpha Bull | C39: Alpha Bull | D39: Creatinas | E39: 55000 | G39: =IF(I39<>"",I39,ROUND(E39*(1-Ajustes!$B$3),-3)) -> 47000 | H39: =IF(F39="","",ROUND(F39*(1-Ajustes!$B$3),-3)) | K39: 10 | L39: No | M39: Sí | N39: products/crea-gold-150g-alpha-bull.jpg
A40: Sí | B40: Magnesio Bisglicinato 60 Perlas Proscience | C40: Proscience | D40: Multivitamínicos | E40: 77000 | G40: =IF(I40<>"",I40,ROUND(E40*(1-Ajustes!$B$3),-3)) -> 65000 | H40: =IF(F40="","",ROUND(F40*(1-Ajustes!$B$3),-3)) | K40: 10 | L40: No | M40: Sí | N40: products/magnesio-bisglicinato-60-perlas-proscience.jpg
...

Sheet Ajustes
A1: Ajustes del catálogo
A3: Descuento frente a la referencia | B3: 0.15
A4: Redondeo | B4: A miles (ej: $118.150 → $118.000)
A6: Cómo usar este archivo
A7: 1. En la hoja Catálogo, edita solo las celdas amarillas (precios propios, sabores, stock, etc.).
A8: 2. Las columnas "Precio NAC" y "Oferta NAC" se calculan solas con el descuento de arriba. Si quieres un precio distinto, escríbelo en "Precio manual".
A9: 3. Marca "No" en la columna Incluir para quitar un producto de la página.
A10: 4. "Marca" dice "Otras marcas (verificar)" cuando el nombre no la deja clara: corrígela.
A11: 5. Guarda cada foto en la carpeta products con el nombre de la columna "Archivo de foto".
A12: 6. Cuando termines, envía este Excel a Claude para actualizar la página.
A13: Precios de referencia: tomados del código de la página guardado el 12/10/2026 (página de inicio).
A14: Se excluyeron 8 combos que son armados propios de la tienda de referencia.
